<?xml version="1.0"?>
<mujoco model="NESM with simple patient">
    <!-- TODO: check if this is agreeing with nesm_with_patient.xacro  -->
    <!-- include path properties -->
    <!-- It is assumed that the generated xml will be located in the 'models/exo_with_patient'
    directory. All relative paths are adjusted accordingly. -->
    <compiler meshdir="../../static/meshes"/>
    <!-- elliptic cones are more realistic, however it is much slower -->
    <option timestep=".005" solver="Newton" impratio="10." tolerance="1e-11" cone="pyramidal" jacobian="sparse" iterations="200"/>
    <size njmax="12000" nconmax="2000"/>
    <default>
        <muscle ctrllimited="true" ctrlrange="0 1"/>
        <site size=".005"/>
        <!-- Human body -->
        <default class="human_body">
            <geom rgba=".5 .5 .5 .4" group="0"/>
            <joint type="hinge" damping=".6" group="0"/>
            <default class="arm">
                <geom contype="1" conaffinity="1"/>
                <default class="hand">
                    <geom friction="1 .005 .001"/>
                    <default class="finger">
                        <geom type="capsule" mass=".01"/>
                        <default class="finger_prox">
                            <geom size=".008"/>
                        </default>
                        <default class="finger_med">
                            <geom size=".0075"/>
                        </default>
                        <default class="finger_dist">
                            <geom size=".007"/>
                        </default>
                        <default class="thumb">
                            <geom size=".009" mass=".005"/>
                        </default>
                    </default>
                </default>
            </default>
            <default class="torso">
                <geom contype="7" conaffinity="7"/>
            </default>
        </default>
        <default class="arm_hard_collider">
            <joint type="hinge" limited="true" range="-.01 .01"/>
            <geom solmix="10" solimp="1 1 .001 .5 2" rgba=".9 .6 .9 .7" group="2"/>
            <default class="uarm_collider">
                <geom contype="2" conaffinity="2"/>
            </default>
            <default class="larm_collider">
                <geom contype="4" conaffinity="4"/>
            </default>
        </default>
        <!-- Exoskeleton classes -->
        <default class="exoskeleton">
            <joint type="hinge" damping="1" limited="true" group="1"/>
        </default>
        <default class="exo_mesh">
            <geom type="mesh" contype="0" conaffinity="0" group="1"/>
            <default class="sAA">
                <geom rgba=".1 .1 .1 1"/>
            </default>
            <default class="sFE">
                <geom rgba=".34 .7 .3 1"/>
            </default>
            <default class="sIE">
                <geom rgba=".35 .7 .87 1"/>
            </default>
            <default class="eFE">
                <geom rgba=".93 .55 .16 1"/>
            </default>
        </default>
        <default class="ua_support">
            <geom contype="2" conaffinity="2" group="3" rgba=".35 .7 .87 1"/>
        </default>
        <default class="la_support">
            <geom contype="4" conaffinity="4" group="3" rgba=".93 .55 .16 1"/>
        </default>
        <default class="exo_motor">
            <motor ctrllimited="true" ctrlrange="-1 1"/>
        </default>
        <default class="strap">
            <equality solimp=".96 .99 .001 .5 2"/>
        </default>
    </default>
    <asset>
        <mesh name="sAA_vsR" file="sAA_very_simple.stl" scale=".0007 .0007 .0007"/>
        <mesh name="sFE_vsR" file="sFE_very_simple.stl" scale=".0007 .0007 .0007"/>
        <mesh name="sIE_vsR" file="sIE_very_simple.stl" scale="-.0007 .0007 .0007"/>
        <mesh name="eFE_vsR" file="eFE_very_simple.stl" scale=".001 .001 .001"/>
        <texture type="skybox" builtin="gradient" rgb1=".6 .6 .9" rgb2="0 0 0" width="512" height="512"/>
        <texture name="texplane" type="2d" builtin="checker" rgb1=".25 .25 .25" rgb2=".3 .3 .3" width="512" height="512" mark="cross" markrgb=".8 .8 .8"/>
        <material name="matplane" reflectance=".3" texture="texplane" texrepeat="1 1" texuniform="true"/>
    </asset>
    <visual>
        <rgba haze=".3 .3 .3 1"/>
    </visual>
    <worldbody>
        <geom name="floor" pos="0 0 -1" size="0 0 1" type="plane" material="matplane"/>
        <light directional="true" diffuse=".8 .8 .8" specular=".2 .2 .2" pos="0 0 5" dir="0 0 -1"/>
        <body name="thorax" pos="-.0157 .2097 .0231" childclass="torso">
            <geom name="torso1" type="capsule" fromto=".0634 -.0586 -.0437 .0634 .0814 -.0437" size=".07"/>
            <geom name="head" type="sphere" pos=".0634 .0114 .1463" size=".09"/>
            <geom name="uwaist" type="capsule" fromto=".0534 -.0486 -.1637 .0534 .0714 -.1637" size=".06"/>
            <geom name="lwaist" type="capsule" fromto=".0534 -.0486 -.3037 .0534 .0714 -.3037" size=".06"/>
            <geom name="butt" type="capsule" fromto=".033 -.0586 -.4687 .033 .0814 -.4687" size=".09"/>
            <body name="clavicle_r">
                <geom name="clavicle_r" type="cylinder" size=".01" fromto="0 0 0 -.0282 -.2077 -.0001"/>
                <body name="scapula_r" pos="-.0282 -.2077 -.0001">
                    <geom name="scapula_r" type="cylinder" size=".01" fromto="0 0 0 .0439 -.002 -.023"/>
                    <inertial pos=".0247 .053 -.0229" mass=".7054" diaginertia=".001 .001 .001"/>
                </body>
            </body>
        </body>
        <body name="Link1" childclass="exoskeleton" xyaxes="0 0 1 0 -1 0">
            <geom name="sAAr" mesh="sAA_vsR" pos="0 0 -.1421" xyaxes="0 0 -1 0 1 0" class="sAA"/>
            <inertial pos="0 0.0191 -0.1279" mass="6.712" fullinertia="0.3787893 0.192833 0.1956839 -0.0006556 -0.0006709 0.0540633"/>
            <joint name="J1" axis="0 0 1" range="-90 0"/>
            <body name="Link2" axisangle="1 0 0 90">
                <geom name="sFEr" mesh="sFE_vsR" pos="0 -.14189 0" quat="0.5 -0.5 0.5 -0.5" class="sFE"/>
                <inertial pos="0.0001 0.0881 -0.1201" mass="3.487" fullinertia=".1108677 .0689688 .0569634 -.0000977 .0000399 .0384741"/>
                <joint name="J2" axis="0 0 1" range="-90 0" ref="-90"/>
                <body name="Link3" pos="0 .25 0" axisangle="1 0 0 -90">
                    <geom name="sIEr" mesh="sIE_vsR" euler="0 -90 0" pos="0 0 -.375" class="sIE"/>
                    <include file="../../bin/models/arm_supports/upper_arm_support.xml"/>
                    <inertial pos="-0.0006 0.1679 -0.03" mass="1.663" fullinertia=".0266938 .007941 .0235228 .0001282 -.0000556 .0038772"/>
                    <joint name="J3" axis="0 0 1" range="-86 30"/>
                    <body name="ua_hard_connector" pos="0.0 -0.0025 -0.135" euler="0 0 -90">
                        <geom name="ua_h_conn" type="cylinder" fromto="0 0 0 -.05 0 0" size=".01" condim="6"/>
                        <body name="humerus_r" childclass="arm" pos=".0 .0 -.13" euler="0 -90 0">
                            <geom name="humerus_r" type="cylinder" size=".01" fromto="0 0 0 0.25077816900000005 -0.005003486 -0.004227083"/>
                            <inertial pos="0.12538908450000003 -0.002501743 -0.0021135415" mass="1.761" diaginertia="0.0013269170625228113 0.009892520545657566 0.009892520545657566"/>
                        </body>
                    </body>
                    <body name="Link4" axisangle="1 0 0 90">
                        <geom name="eFEr" mesh="eFE_vsR" pos="0 0 -.11" quat="0.61237244 -0.35355339 0.61237244 0.35355339" class="eFE"/>
                        <include file="../../bin/models/arm_supports/lower_arm_support.xml"/>
                        <inertial pos="0 0.0707 -0.0803" mass=".494" fullinertia=".0069974 .0035498 .0037622 -.0000009 -.0000004 .001812"/>
                        <joint name="J4" axis="0 0 -1" range="0 125" frictionloss="2.7868500893593593"/>
                        <body name="la_hard_connector" pos="0.0 0.135 -0.015" euler="0 90 180">
                            <geom name="la_h_conn" type="cylinder" fromto="0 0 0 -.025 0 0" size=".01" condim="6"/>

                            <body name="ulna_r" pos=".025 .15 -.015" childclass="arm" euler="0 0 -90">
                                <geom name="ulna_r" type="cylinder" size=".01" fromto="0 0 0 .0133 -.0171 .0163"/>
                                <inertial pos="0.13915 -0.00855 0.00815" mass="0.481" diaginertia="0.00021644999999999998 0.0029230770833333333 0.0029230770833333333"/>

                                <body name="radius_r" pos=".0133 -.0171 .0163">

                                    <geom name="radius_r" type="cylinder" size=".01" fromto="0 0 0 .263 0 0"/>
                                    <inertial pos="0.1325 0.0 0.0" mass="0.481" diaginertia="0.00021644999999999998 0.0029230770833333333 0.0029230770833333333"/>

                                    <body name="hand_r" pos=".265 0 0" childclass="hand">
                                        <geom name="palm" type="box" size=".045 .04 .01" pos=".045 0 0" mass=".5"/>

                                        <body name="fingers_prox" pos=".09 0 0" childclass="finger_prox">
                                            <geom name="FFP" fromto="0 .024 0 .03 .024 0"/>
                                            <geom name="MFP" fromto="0 -.008 0 .03 -.008 0"/>
                                            <geom name="RFP" fromto="0 .008 0 .03 .008 0"/>
                                            <geom name="LFP" fromto="0 -.024 0 .03 -.024 0"/>


                                            <body name="fingers_med" pos=".03 0 0" childclass="finger_med">
                                                <geom name="FFM" fromto="0 .024 0 .03 .024 -.01"/>
                                                <geom name="RFM" fromto="0 .008 0 .03 .008 -.01"/>
                                                <geom name="MFM" fromto="0 -.008 0 .03 -.008 -.01"/>
                                                <geom name="LFM" fromto="0 -.024 0 .03 -.024 -.01"/>


                                                <body name="fingers_dist" childclass="finger_dist">
                                                    <geom name="FFD" fromto=".03 .024 -.01 .045 .024 -.018"/>
                                                    <geom name="MFD" fromto=".03 -.008 -.01 .045 -.008 -.018"/>
                                                    <geom name="RFD" fromto=".03 .008 -.01 .045 .008 -.018"/>
                                                    <geom name="LFD" fromto=".03 -.024 -.01 .045 -.024 -.018"/>
                                                </body>
                                            </body>
                                        </body>

                                        <body name="thumb" pos=".03 .04 0" childclass="thumb">
                                            <geom name="THP" fromto="0 0 0 .02 .025 -.01"/>
                                            <geom name="THM" fromto=".02 .025 -.01 .045 .035 -.018"/>
                                            <geom name="THD" fromto=".045 .035 -.018 .058 .035 -.022"/>

                                        </body>
                                    </body>
                                </body>
                            </body>
                        </body>
                    </body>
                </body>
            </body>
        </body>
    </worldbody>
    <actuator>
        <!-- Exoskeleton actuators ctrlrange="-60 60" -->
        <motor name="sAA" gear="60" joint="J1" class="exo_motor"/>
        <motor name="sFE" gear="60" joint="J2" class="exo_motor"/>
        <motor name="sIE" gear="60" joint="J3" class="exo_motor"/>
        <motor name="eFE" gear="60" joint="J4" class="exo_motor"/>
    </actuator>
    <contact>
        <exclude body1="clavicle_r" body2="scapula_r"/>
        <exclude body1="scapula_r" body2="humerus_r"/>
        <exclude body1="humerus_r" body2="ulna_r"/>
        <exclude body1="humerus_r" body2="radius_r"/>
        <exclude body1="ulna_r" body2="radius_r"/>
        <exclude body1="radius_r" body2="hand_r"/>
        <exclude body1="hand_r" body2="fingers_prox"/>
        <exclude body1="fingers_prox" body2="fingers_med"/>
    </contact>
</mujoco>